[2024-04-04T13:53:46.004+0000] {taskinstance.py:1979} INFO - Dependencies all met for dep_context=non-requeueable deps ti=<TaskInstance: conrad_coding_test.task_1_ingestion manual__2024-04-04T13:53:41.615420+00:00 [queued]>
[2024-04-04T13:53:46.013+0000] {taskinstance.py:1979} INFO - Dependencies all met for dep_context=requeueable deps ti=<TaskInstance: conrad_coding_test.task_1_ingestion manual__2024-04-04T13:53:41.615420+00:00 [queued]>
[2024-04-04T13:53:46.013+0000] {taskinstance.py:2193} INFO - Starting attempt 1 of 2
[2024-04-04T13:53:46.034+0000] {taskinstance.py:2217} INFO - Executing <Task(PythonOperator): task_1_ingestion> on 2024-04-04 13:53:41.615420+00:00
[2024-04-04T13:53:46.046+0000] {standard_task_runner.py:60} INFO - Started process 163241 to run task
[2024-04-04T13:53:46.058+0000] {standard_task_runner.py:87} INFO - Running: ['airflow', 'tasks', 'run', 'conrad_coding_test', 'task_1_ingestion', 'manual__2024-04-04T13:53:41.615420+00:00', '--job-id', '40', '--raw', '--subdir', 'DAGS_FOLDER/dag_spark_multi_source_test_docker.py', '--cfg-path', '/tmp/tmpbh3q04pe']
[2024-04-04T13:53:46.065+0000] {standard_task_runner.py:88} INFO - Job 40: Subtask task_1_ingestion
[2024-04-04T13:53:46.139+0000] {task_command.py:423} INFO - Running <TaskInstance: conrad_coding_test.task_1_ingestion manual__2024-04-04T13:53:41.615420+00:00 [running]> on host de-zoomcamp.us-central1-a.c.my-zhe-414813.internal
[2024-04-04T13:53:46.231+0000] {taskinstance.py:2513} INFO - Exporting env vars: AIRFLOW_CTX_DAG_OWNER='airflow' AIRFLOW_CTX_DAG_ID='conrad_coding_test' AIRFLOW_CTX_TASK_ID='task_1_ingestion' AIRFLOW_CTX_EXECUTION_DATE='2024-04-04T13:53:41.615420+00:00' AIRFLOW_CTX_TRY_NUMBER='1' AIRFLOW_CTX_DAG_RUN_ID='manual__2024-04-04T13:53:41.615420+00:00'
[2024-04-04T13:53:46.858+0000] {taskinstance.py:2731} ERROR - Task failed with exception
Traceback (most recent call last):
  File "/home/datatalks_jan/anaconda3/lib/python3.11/site-packages/airflow/models/taskinstance.py", line 444, in _execute_task
    result = _execute_callable(context=context, **execute_callable_kwargs)
             ^^^^^^^^^^^^^^^^^^^^^^^^^^^^^^^^^^^^^^^^^^^^^^^^^^^^^^^^^^^^^
  File "/home/datatalks_jan/anaconda3/lib/python3.11/site-packages/airflow/models/taskinstance.py", line 414, in _execute_callable
    return execute_callable(context=context, **execute_callable_kwargs)
           ^^^^^^^^^^^^^^^^^^^^^^^^^^^^^^^^^^^^^^^^^^^^^^^^^^^^^^^^^^^^
  File "/home/datatalks_jan/anaconda3/lib/python3.11/site-packages/airflow/operators/python.py", line 200, in execute
    return_value = self.execute_callable()
                   ^^^^^^^^^^^^^^^^^^^^^^^
  File "/home/datatalks_jan/anaconda3/lib/python3.11/site-packages/airflow/operators/python.py", line 217, in execute_callable
    return self.python_callable(*self.op_args, **self.op_kwargs)
           ^^^^^^^^^^^^^^^^^^^^^^^^^^^^^^^^^^^^^^^^^^^^^^^^^^^^^
  File "/home/datatalks_jan/Data_Eden/3_airflow_demo/airflow/dags/dag_spark_multi_source_test_docker.py", line 16, in download_and_unzip_data
    gdown.download(source_url, output_file, quiet=False)
  File "/home/datatalks_jan/anaconda3/lib/python3.11/site-packages/gdown/download.py", line 283, in download
    for file in os.listdir(osp.dirname(output) or "."):
                ^^^^^^^^^^^^^^^^^^^^^^^^^^^^^^^^^^^^^^
FileNotFoundError: [Errno 2] No such file or directory: 'source_data/multi_source_data'
[2024-04-04T13:53:46.868+0000] {taskinstance.py:1149} INFO - Marking task as UP_FOR_RETRY. dag_id=conrad_coding_test, task_id=task_1_ingestion, execution_date=20240404T135341, start_date=20240404T135346, end_date=20240404T135346
[2024-04-04T13:53:46.886+0000] {standard_task_runner.py:107} ERROR - Failed to execute job 40 for task task_1_ingestion ([Errno 2] No such file or directory: 'source_data/multi_source_data'; 163241)
[2024-04-04T13:53:46.913+0000] {local_task_job_runner.py:234} INFO - Task exited with return code 1
[2024-04-04T13:53:46.938+0000] {taskinstance.py:3312} INFO - 0 downstream tasks scheduled from follow-on schedule check
