[2024-04-04T13:44:51.954+0000] {taskinstance.py:1979} INFO - Dependencies all met for dep_context=non-requeueable deps ti=<TaskInstance: conrad_coding_test.task_1_ingestion manual__2024-04-04T13:42:13.382085+00:00 [queued]>
[2024-04-04T13:44:51.962+0000] {taskinstance.py:1979} INFO - Dependencies all met for dep_context=requeueable deps ti=<TaskInstance: conrad_coding_test.task_1_ingestion manual__2024-04-04T13:42:13.382085+00:00 [queued]>
[2024-04-04T13:44:51.963+0000] {taskinstance.py:2193} INFO - Starting attempt 2 of 2
[2024-04-04T13:44:51.978+0000] {taskinstance.py:2217} INFO - Executing <Task(PythonOperator): task_1_ingestion> on 2024-04-04 13:42:13.382085+00:00
[2024-04-04T13:44:51.991+0000] {standard_task_runner.py:60} INFO - Started process 161781 to run task
[2024-04-04T13:44:52.002+0000] {standard_task_runner.py:87} INFO - Running: ['airflow', 'tasks', 'run', 'conrad_coding_test', 'task_1_ingestion', 'manual__2024-04-04T13:42:13.382085+00:00', '--job-id', '39', '--raw', '--subdir', 'DAGS_FOLDER/dag_spark_multi_source_test_docker.py', '--cfg-path', '/tmp/tmprbyspp_9']
[2024-04-04T13:44:52.008+0000] {standard_task_runner.py:88} INFO - Job 39: Subtask task_1_ingestion
[2024-04-04T13:44:52.085+0000] {task_command.py:423} INFO - Running <TaskInstance: conrad_coding_test.task_1_ingestion manual__2024-04-04T13:42:13.382085+00:00 [running]> on host de-zoomcamp.us-central1-a.c.my-zhe-414813.internal
[2024-04-04T13:44:52.178+0000] {taskinstance.py:2513} INFO - Exporting env vars: AIRFLOW_CTX_DAG_OWNER='airflow' AIRFLOW_CTX_DAG_ID='conrad_coding_test' AIRFLOW_CTX_TASK_ID='task_1_ingestion' AIRFLOW_CTX_EXECUTION_DATE='2024-04-04T13:42:13.382085+00:00' AIRFLOW_CTX_TRY_NUMBER='2' AIRFLOW_CTX_DAG_RUN_ID='manual__2024-04-04T13:42:13.382085+00:00'
[2024-04-04T13:44:53.050+0000] {taskinstance.py:2731} ERROR - Task failed with exception
Traceback (most recent call last):
  File "/home/datatalks_jan/anaconda3/lib/python3.11/site-packages/airflow/models/taskinstance.py", line 444, in _execute_task
    result = _execute_callable(context=context, **execute_callable_kwargs)
             ^^^^^^^^^^^^^^^^^^^^^^^^^^^^^^^^^^^^^^^^^^^^^^^^^^^^^^^^^^^^^
  File "/home/datatalks_jan/anaconda3/lib/python3.11/site-packages/airflow/models/taskinstance.py", line 414, in _execute_callable
    return execute_callable(context=context, **execute_callable_kwargs)
           ^^^^^^^^^^^^^^^^^^^^^^^^^^^^^^^^^^^^^^^^^^^^^^^^^^^^^^^^^^^^
  File "/home/datatalks_jan/anaconda3/lib/python3.11/site-packages/airflow/operators/python.py", line 200, in execute
    return_value = self.execute_callable()
                   ^^^^^^^^^^^^^^^^^^^^^^^
  File "/home/datatalks_jan/anaconda3/lib/python3.11/site-packages/airflow/operators/python.py", line 217, in execute_callable
    return self.python_callable(*self.op_args, **self.op_kwargs)
           ^^^^^^^^^^^^^^^^^^^^^^^^^^^^^^^^^^^^^^^^^^^^^^^^^^^^^
  File "/home/datatalks_jan/Data_Eden/3_airflow_demo/airflow/dags/dag_spark_multi_source_test_docker.py", line 16, in download_and_unzip_data
    gdown.download(source_url, output_file, quiet=False)
  File "/home/datatalks_jan/anaconda3/lib/python3.11/site-packages/gdown/download.py", line 283, in download
    for file in os.listdir(osp.dirname(output) or "."):
                ^^^^^^^^^^^^^^^^^^^^^^^^^^^^^^^^^^^^^^
FileNotFoundError: [Errno 2] No such file or directory: 'source_data/multi_source_data'
[2024-04-04T13:44:53.059+0000] {taskinstance.py:1149} INFO - Marking task as FAILED. dag_id=conrad_coding_test, task_id=task_1_ingestion, execution_date=20240404T134213, start_date=20240404T134451, end_date=20240404T134453
[2024-04-04T13:44:53.074+0000] {standard_task_runner.py:107} ERROR - Failed to execute job 39 for task task_1_ingestion ([Errno 2] No such file or directory: 'source_data/multi_source_data'; 161781)
[2024-04-04T13:44:53.099+0000] {local_task_job_runner.py:234} INFO - Task exited with return code 1
[2024-04-04T13:44:53.116+0000] {taskinstance.py:3312} INFO - 0 downstream tasks scheduled from follow-on schedule check
