[2024-04-04T14:02:42.066+0000] {taskinstance.py:1979} INFO - Dependencies all met for dep_context=non-requeueable deps ti=<TaskInstance: conrad_coding_test.task_3_data_output manual__2024-04-04T14:01:58.875594+00:00 [queued]>
[2024-04-04T14:02:42.075+0000] {taskinstance.py:1979} INFO - Dependencies all met for dep_context=requeueable deps ti=<TaskInstance: conrad_coding_test.task_3_data_output manual__2024-04-04T14:01:58.875594+00:00 [queued]>
[2024-04-04T14:02:42.075+0000] {taskinstance.py:2193} INFO - Starting attempt 1 of 2
[2024-04-04T14:02:42.089+0000] {taskinstance.py:2217} INFO - Executing <Task(PythonOperator): task_3_data_output> on 2024-04-04 14:01:58.875594+00:00
[2024-04-04T14:02:42.096+0000] {standard_task_runner.py:60} INFO - Started process 167015 to run task
[2024-04-04T14:02:42.103+0000] {standard_task_runner.py:87} INFO - Running: ['airflow', 'tasks', 'run', 'conrad_coding_test', 'task_3_data_output', 'manual__2024-04-04T14:01:58.875594+00:00', '--job-id', '49', '--raw', '--subdir', 'DAGS_FOLDER/dag_spark_multi_source_test_docker.py', '--cfg-path', '/tmp/tmpo_b9l8dc']
[2024-04-04T14:02:42.106+0000] {standard_task_runner.py:88} INFO - Job 49: Subtask task_3_data_output
[2024-04-04T14:02:42.149+0000] {task_command.py:423} INFO - Running <TaskInstance: conrad_coding_test.task_3_data_output manual__2024-04-04T14:01:58.875594+00:00 [running]> on host de-zoomcamp.us-central1-a.c.my-zhe-414813.internal
[2024-04-04T14:02:42.215+0000] {taskinstance.py:2513} INFO - Exporting env vars: AIRFLOW_CTX_DAG_OWNER='airflow' AIRFLOW_CTX_DAG_ID='conrad_coding_test' AIRFLOW_CTX_TASK_ID='task_3_data_output' AIRFLOW_CTX_EXECUTION_DATE='2024-04-04T14:01:58.875594+00:00' AIRFLOW_CTX_TRY_NUMBER='1' AIRFLOW_CTX_DAG_RUN_ID='manual__2024-04-04T14:01:58.875594+00:00'
[2024-04-04T14:02:42.224+0000] {taskinstance.py:2731} ERROR - Task failed with exception
Traceback (most recent call last):
  File "/home/datatalks_jan/anaconda3/lib/python3.11/site-packages/airflow/models/taskinstance.py", line 444, in _execute_task
    result = _execute_callable(context=context, **execute_callable_kwargs)
             ^^^^^^^^^^^^^^^^^^^^^^^^^^^^^^^^^^^^^^^^^^^^^^^^^^^^^^^^^^^^^
  File "/home/datatalks_jan/anaconda3/lib/python3.11/site-packages/airflow/models/taskinstance.py", line 414, in _execute_callable
    return execute_callable(context=context, **execute_callable_kwargs)
           ^^^^^^^^^^^^^^^^^^^^^^^^^^^^^^^^^^^^^^^^^^^^^^^^^^^^^^^^^^^^
  File "/home/datatalks_jan/anaconda3/lib/python3.11/site-packages/airflow/operators/python.py", line 200, in execute
    return_value = self.execute_callable()
                   ^^^^^^^^^^^^^^^^^^^^^^^
  File "/home/datatalks_jan/anaconda3/lib/python3.11/site-packages/airflow/operators/python.py", line 217, in execute_callable
    return self.python_callable(*self.op_args, **self.op_kwargs)
           ^^^^^^^^^^^^^^^^^^^^^^^^^^^^^^^^^^^^^^^^^^^^^^^^^^^^^
  File "/home/datatalks_jan/Data_Eden/3_airflow_demo/airflow/dags/dag_spark_multi_source_test_docker.py", line 27, in data_outbound_GCS
    upload_to_gcs(local_file_path, gcs_bucket_name, gcs_file_path)
    ^^^^^^^^^^^^^
NameError: name 'upload_to_gcs' is not defined
[2024-04-04T14:02:42.230+0000] {taskinstance.py:1149} INFO - Marking task as UP_FOR_RETRY. dag_id=conrad_coding_test, task_id=task_3_data_output, execution_date=20240404T140158, start_date=20240404T140242, end_date=20240404T140242
[2024-04-04T14:02:42.241+0000] {standard_task_runner.py:107} ERROR - Failed to execute job 49 for task task_3_data_output (name 'upload_to_gcs' is not defined; 167015)
[2024-04-04T14:02:42.274+0000] {local_task_job_runner.py:234} INFO - Task exited with return code 1
[2024-04-04T14:02:42.296+0000] {taskinstance.py:3312} INFO - 0 downstream tasks scheduled from follow-on schedule check
