[2024-04-04T13:33:45.213+0000] {taskinstance.py:1979} INFO - Dependencies all met for dep_context=non-requeueable deps ti=<TaskInstance: conrad_coding_test.task_3_data_output manual__2024-04-04T13:33:11.885627+00:00 [queued]>
[2024-04-04T13:33:45.219+0000] {taskinstance.py:1979} INFO - Dependencies all met for dep_context=requeueable deps ti=<TaskInstance: conrad_coding_test.task_3_data_output manual__2024-04-04T13:33:11.885627+00:00 [queued]>
[2024-04-04T13:33:45.219+0000] {taskinstance.py:2193} INFO - Starting attempt 1 of 2
[2024-04-04T13:33:45.233+0000] {taskinstance.py:2217} INFO - Executing <Task(PythonOperator): task_3_data_output> on 2024-04-04 13:33:11.885627+00:00
[2024-04-04T13:33:45.243+0000] {standard_task_runner.py:60} INFO - Started process 159487 to run task
[2024-04-04T13:33:45.250+0000] {standard_task_runner.py:87} INFO - Running: ['airflow', 'tasks', 'run', 'conrad_coding_test', 'task_3_data_output', 'manual__2024-04-04T13:33:11.885627+00:00', '--job-id', '33', '--raw', '--subdir', 'DAGS_FOLDER/dag_spark_multi_source_test_docker.py', '--cfg-path', '/tmp/tmpebj_5gxv']
[2024-04-04T13:33:45.253+0000] {standard_task_runner.py:88} INFO - Job 33: Subtask task_3_data_output
[2024-04-04T13:33:45.300+0000] {task_command.py:423} INFO - Running <TaskInstance: conrad_coding_test.task_3_data_output manual__2024-04-04T13:33:11.885627+00:00 [running]> on host de-zoomcamp.us-central1-a.c.my-zhe-414813.internal
[2024-04-04T13:33:45.360+0000] {taskinstance.py:2513} INFO - Exporting env vars: AIRFLOW_CTX_DAG_OWNER='airflow' AIRFLOW_CTX_DAG_ID='conrad_coding_test' AIRFLOW_CTX_TASK_ID='task_3_data_output' AIRFLOW_CTX_EXECUTION_DATE='2024-04-04T13:33:11.885627+00:00' AIRFLOW_CTX_TRY_NUMBER='1' AIRFLOW_CTX_DAG_RUN_ID='manual__2024-04-04T13:33:11.885627+00:00'
[2024-04-04T13:33:45.368+0000] {taskinstance.py:2731} ERROR - Task failed with exception
Traceback (most recent call last):
  File "/home/datatalks_jan/anaconda3/lib/python3.11/site-packages/airflow/models/taskinstance.py", line 444, in _execute_task
    result = _execute_callable(context=context, **execute_callable_kwargs)
             ^^^^^^^^^^^^^^^^^^^^^^^^^^^^^^^^^^^^^^^^^^^^^^^^^^^^^^^^^^^^^
  File "/home/datatalks_jan/anaconda3/lib/python3.11/site-packages/airflow/models/taskinstance.py", line 414, in _execute_callable
    return execute_callable(context=context, **execute_callable_kwargs)
           ^^^^^^^^^^^^^^^^^^^^^^^^^^^^^^^^^^^^^^^^^^^^^^^^^^^^^^^^^^^^
  File "/home/datatalks_jan/anaconda3/lib/python3.11/site-packages/airflow/operators/python.py", line 200, in execute
    return_value = self.execute_callable()
                   ^^^^^^^^^^^^^^^^^^^^^^^
  File "/home/datatalks_jan/anaconda3/lib/python3.11/site-packages/airflow/operators/python.py", line 217, in execute_callable
    return self.python_callable(*self.op_args, **self.op_kwargs)
           ^^^^^^^^^^^^^^^^^^^^^^^^^^^^^^^^^^^^^^^^^^^^^^^^^^^^^
  File "/home/datatalks_jan/Data_Eden/3_airflow_demo/airflow/dags/dag_spark_multi_source_test_docker.py", line 14, in data_outbound_GCS
    df_final[0].write.csv("gs://my-zhe-414813/conrad_output", mode="overwrite", header=True, inferSchema=True)
    ^^^^^^^^^^^^^^^^^
AttributeError: 'str' object has no attribute 'write'
[2024-04-04T13:33:45.376+0000] {taskinstance.py:1149} INFO - Marking task as UP_FOR_RETRY. dag_id=conrad_coding_test, task_id=task_3_data_output, execution_date=20240404T133311, start_date=20240404T133345, end_date=20240404T133345
[2024-04-04T13:33:45.387+0000] {standard_task_runner.py:107} ERROR - Failed to execute job 33 for task task_3_data_output ('str' object has no attribute 'write'; 159487)
[2024-04-04T13:33:45.421+0000] {local_task_job_runner.py:234} INFO - Task exited with return code 1
[2024-04-04T13:33:45.436+0000] {taskinstance.py:3312} INFO - 0 downstream tasks scheduled from follow-on schedule check
