[2024-04-04T12:57:43.830+0000] {taskinstance.py:1979} INFO - Dependencies all met for dep_context=non-requeueable deps ti=<TaskInstance: conrad_coding_test.task_3_data_output manual__2024-04-04T12:57:03.177273+00:00 [queued]>
[2024-04-04T12:57:43.836+0000] {taskinstance.py:1979} INFO - Dependencies all met for dep_context=requeueable deps ti=<TaskInstance: conrad_coding_test.task_3_data_output manual__2024-04-04T12:57:03.177273+00:00 [queued]>
[2024-04-04T12:57:43.837+0000] {taskinstance.py:2193} INFO - Starting attempt 1 of 2
[2024-04-04T12:57:43.851+0000] {taskinstance.py:2217} INFO - Executing <Task(PythonOperator): task_3_data_output> on 2024-04-04 12:57:03.177273+00:00
[2024-04-04T12:57:43.860+0000] {standard_task_runner.py:60} INFO - Started process 154858 to run task
[2024-04-04T12:57:43.867+0000] {standard_task_runner.py:87} INFO - Running: ['airflow', 'tasks', 'run', 'conrad_coding_test', 'task_3_data_output', 'manual__2024-04-04T12:57:03.177273+00:00', '--job-id', '28', '--raw', '--subdir', 'DAGS_FOLDER/dag_spark_multi_source_test_docker.py', '--cfg-path', '/tmp/tmp0ln4zuf8']
[2024-04-04T12:57:43.871+0000] {standard_task_runner.py:88} INFO - Job 28: Subtask task_3_data_output
[2024-04-04T12:57:43.916+0000] {task_command.py:423} INFO - Running <TaskInstance: conrad_coding_test.task_3_data_output manual__2024-04-04T12:57:03.177273+00:00 [running]> on host de-zoomcamp.us-central1-a.c.my-zhe-414813.internal
[2024-04-04T12:57:43.977+0000] {taskinstance.py:2513} INFO - Exporting env vars: AIRFLOW_CTX_DAG_OWNER='airflow' AIRFLOW_CTX_DAG_ID='conrad_coding_test' AIRFLOW_CTX_TASK_ID='task_3_data_output' AIRFLOW_CTX_EXECUTION_DATE='2024-04-04T12:57:03.177273+00:00' AIRFLOW_CTX_TRY_NUMBER='1' AIRFLOW_CTX_DAG_RUN_ID='manual__2024-04-04T12:57:03.177273+00:00'
[2024-04-04T12:57:43.987+0000] {taskinstance.py:2731} ERROR - Task failed with exception
Traceback (most recent call last):
  File "/home/datatalks_jan/anaconda3/lib/python3.11/site-packages/airflow/models/taskinstance.py", line 444, in _execute_task
    result = _execute_callable(context=context, **execute_callable_kwargs)
             ^^^^^^^^^^^^^^^^^^^^^^^^^^^^^^^^^^^^^^^^^^^^^^^^^^^^^^^^^^^^^
  File "/home/datatalks_jan/anaconda3/lib/python3.11/site-packages/airflow/models/taskinstance.py", line 414, in _execute_callable
    return execute_callable(context=context, **execute_callable_kwargs)
           ^^^^^^^^^^^^^^^^^^^^^^^^^^^^^^^^^^^^^^^^^^^^^^^^^^^^^^^^^^^^
  File "/home/datatalks_jan/anaconda3/lib/python3.11/site-packages/airflow/operators/python.py", line 200, in execute
    return_value = self.execute_callable()
                   ^^^^^^^^^^^^^^^^^^^^^^^
  File "/home/datatalks_jan/anaconda3/lib/python3.11/site-packages/airflow/operators/python.py", line 217, in execute_callable
    return self.python_callable(*self.op_args, **self.op_kwargs)
           ^^^^^^^^^^^^^^^^^^^^^^^^^^^^^^^^^^^^^^^^^^^^^^^^^^^^^
  File "/home/datatalks_jan/Data_Eden/3_airflow_demo/airflow/dags/dag_spark_multi_source_test_docker.py", line 16, in data_outbound_GCS
    df_final.write.text(output_path, mode="overwrite")
    ^^^^^^^^^^^^^^
AttributeError: 'list' object has no attribute 'write'
[2024-04-04T12:57:43.996+0000] {taskinstance.py:1149} INFO - Marking task as UP_FOR_RETRY. dag_id=conrad_coding_test, task_id=task_3_data_output, execution_date=20240404T125703, start_date=20240404T125743, end_date=20240404T125743
[2024-04-04T12:57:44.011+0000] {standard_task_runner.py:107} ERROR - Failed to execute job 28 for task task_3_data_output ('list' object has no attribute 'write'; 154858)
[2024-04-04T12:57:44.039+0000] {local_task_job_runner.py:234} INFO - Task exited with return code 1
[2024-04-04T12:57:44.054+0000] {taskinstance.py:3312} INFO - 0 downstream tasks scheduled from follow-on schedule check
