[2024-04-04T12:58:47.506+0000] {taskinstance.py:1979} INFO - Dependencies all met for dep_context=non-requeueable deps ti=<TaskInstance: conrad_coding_test.task_3_data_output manual__2024-04-04T12:57:03.177273+00:00 [queued]>
[2024-04-04T12:58:47.513+0000] {taskinstance.py:1979} INFO - Dependencies all met for dep_context=requeueable deps ti=<TaskInstance: conrad_coding_test.task_3_data_output manual__2024-04-04T12:57:03.177273+00:00 [queued]>
[2024-04-04T12:58:47.514+0000] {taskinstance.py:2193} INFO - Starting attempt 2 of 2
[2024-04-04T12:58:47.529+0000] {taskinstance.py:2217} INFO - Executing <Task(PythonOperator): task_3_data_output> on 2024-04-04 12:57:03.177273+00:00
[2024-04-04T12:58:47.539+0000] {standard_task_runner.py:60} INFO - Started process 155404 to run task
[2024-04-04T12:58:47.546+0000] {standard_task_runner.py:87} INFO - Running: ['airflow', 'tasks', 'run', 'conrad_coding_test', 'task_3_data_output', 'manual__2024-04-04T12:57:03.177273+00:00', '--job-id', '29', '--raw', '--subdir', 'DAGS_FOLDER/dag_spark_multi_source_test_docker.py', '--cfg-path', '/tmp/tmp2k1ux3wv']
[2024-04-04T12:58:47.549+0000] {standard_task_runner.py:88} INFO - Job 29: Subtask task_3_data_output
[2024-04-04T12:58:47.601+0000] {task_command.py:423} INFO - Running <TaskInstance: conrad_coding_test.task_3_data_output manual__2024-04-04T12:57:03.177273+00:00 [running]> on host de-zoomcamp.us-central1-a.c.my-zhe-414813.internal
[2024-04-04T12:58:47.660+0000] {taskinstance.py:2513} INFO - Exporting env vars: AIRFLOW_CTX_DAG_OWNER='airflow' AIRFLOW_CTX_DAG_ID='conrad_coding_test' AIRFLOW_CTX_TASK_ID='task_3_data_output' AIRFLOW_CTX_EXECUTION_DATE='2024-04-04T12:57:03.177273+00:00' AIRFLOW_CTX_TRY_NUMBER='2' AIRFLOW_CTX_DAG_RUN_ID='manual__2024-04-04T12:57:03.177273+00:00'
[2024-04-04T12:58:47.670+0000] {taskinstance.py:2731} ERROR - Task failed with exception
Traceback (most recent call last):
  File "/home/datatalks_jan/anaconda3/lib/python3.11/site-packages/airflow/models/taskinstance.py", line 444, in _execute_task
    result = _execute_callable(context=context, **execute_callable_kwargs)
             ^^^^^^^^^^^^^^^^^^^^^^^^^^^^^^^^^^^^^^^^^^^^^^^^^^^^^^^^^^^^^
  File "/home/datatalks_jan/anaconda3/lib/python3.11/site-packages/airflow/models/taskinstance.py", line 414, in _execute_callable
    return execute_callable(context=context, **execute_callable_kwargs)
           ^^^^^^^^^^^^^^^^^^^^^^^^^^^^^^^^^^^^^^^^^^^^^^^^^^^^^^^^^^^^
  File "/home/datatalks_jan/anaconda3/lib/python3.11/site-packages/airflow/operators/python.py", line 200, in execute
    return_value = self.execute_callable()
                   ^^^^^^^^^^^^^^^^^^^^^^^
  File "/home/datatalks_jan/anaconda3/lib/python3.11/site-packages/airflow/operators/python.py", line 217, in execute_callable
    return self.python_callable(*self.op_args, **self.op_kwargs)
           ^^^^^^^^^^^^^^^^^^^^^^^^^^^^^^^^^^^^^^^^^^^^^^^^^^^^^
  File "/home/datatalks_jan/Data_Eden/3_airflow_demo/airflow/dags/dag_spark_multi_source_test_docker.py", line 16, in data_outbound_GCS
    df_final.write.text(output_path, mode="overwrite")
    ^^^^^^^^^^^^^^
AttributeError: 'list' object has no attribute 'write'
[2024-04-04T12:58:47.675+0000] {taskinstance.py:1149} INFO - Marking task as FAILED. dag_id=conrad_coding_test, task_id=task_3_data_output, execution_date=20240404T125703, start_date=20240404T125847, end_date=20240404T125847
[2024-04-04T12:58:47.688+0000] {standard_task_runner.py:107} ERROR - Failed to execute job 29 for task task_3_data_output ('list' object has no attribute 'write'; 155404)
[2024-04-04T12:58:47.718+0000] {local_task_job_runner.py:234} INFO - Task exited with return code 1
[2024-04-04T12:58:47.735+0000] {taskinstance.py:3312} INFO - 0 downstream tasks scheduled from follow-on schedule check
