[2024-04-04T13:42:47.394+0000] {taskinstance.py:1979} INFO - Dependencies all met for dep_context=non-requeueable deps ti=<TaskInstance: conrad_coding_test.task_3_data_output manual__2024-04-04T13:42:13.382085+00:00 [queued]>
[2024-04-04T13:42:47.400+0000] {taskinstance.py:1979} INFO - Dependencies all met for dep_context=requeueable deps ti=<TaskInstance: conrad_coding_test.task_3_data_output manual__2024-04-04T13:42:13.382085+00:00 [queued]>
[2024-04-04T13:42:47.401+0000] {taskinstance.py:2193} INFO - Starting attempt 1 of 2
[2024-04-04T13:42:47.415+0000] {taskinstance.py:2217} INFO - Executing <Task(PythonOperator): task_3_data_output> on 2024-04-04 13:42:13.382085+00:00
[2024-04-04T13:42:47.425+0000] {standard_task_runner.py:60} INFO - Started process 160901 to run task
[2024-04-04T13:42:47.432+0000] {standard_task_runner.py:87} INFO - Running: ['airflow', 'tasks', 'run', 'conrad_coding_test', 'task_3_data_output', 'manual__2024-04-04T13:42:13.382085+00:00', '--job-id', '36', '--raw', '--subdir', 'DAGS_FOLDER/dag_spark_multi_source_test_docker.py', '--cfg-path', '/tmp/tmpl7lra_h5']
[2024-04-04T13:42:47.435+0000] {standard_task_runner.py:88} INFO - Job 36: Subtask task_3_data_output
[2024-04-04T13:42:47.482+0000] {task_command.py:423} INFO - Running <TaskInstance: conrad_coding_test.task_3_data_output manual__2024-04-04T13:42:13.382085+00:00 [running]> on host de-zoomcamp.us-central1-a.c.my-zhe-414813.internal
[2024-04-04T13:42:47.545+0000] {taskinstance.py:2513} INFO - Exporting env vars: AIRFLOW_CTX_DAG_OWNER='airflow' AIRFLOW_CTX_DAG_ID='conrad_coding_test' AIRFLOW_CTX_TASK_ID='task_3_data_output' AIRFLOW_CTX_EXECUTION_DATE='2024-04-04T13:42:13.382085+00:00' AIRFLOW_CTX_TRY_NUMBER='1' AIRFLOW_CTX_DAG_RUN_ID='manual__2024-04-04T13:42:13.382085+00:00'
[2024-04-04T13:42:47.554+0000] {taskinstance.py:2731} ERROR - Task failed with exception
Traceback (most recent call last):
  File "/home/datatalks_jan/anaconda3/lib/python3.11/site-packages/airflow/models/taskinstance.py", line 444, in _execute_task
    result = _execute_callable(context=context, **execute_callable_kwargs)
             ^^^^^^^^^^^^^^^^^^^^^^^^^^^^^^^^^^^^^^^^^^^^^^^^^^^^^^^^^^^^^
  File "/home/datatalks_jan/anaconda3/lib/python3.11/site-packages/airflow/models/taskinstance.py", line 414, in _execute_callable
    return execute_callable(context=context, **execute_callable_kwargs)
           ^^^^^^^^^^^^^^^^^^^^^^^^^^^^^^^^^^^^^^^^^^^^^^^^^^^^^^^^^^^^
  File "/home/datatalks_jan/anaconda3/lib/python3.11/site-packages/airflow/operators/python.py", line 200, in execute
    return_value = self.execute_callable()
                   ^^^^^^^^^^^^^^^^^^^^^^^
  File "/home/datatalks_jan/anaconda3/lib/python3.11/site-packages/airflow/operators/python.py", line 217, in execute_callable
    return self.python_callable(*self.op_args, **self.op_kwargs)
           ^^^^^^^^^^^^^^^^^^^^^^^^^^^^^^^^^^^^^^^^^^^^^^^^^^^^^
  File "/home/datatalks_jan/Data_Eden/3_airflow_demo/airflow/dags/dag_spark_multi_source_test_docker.py", line 14, in data_outbound_GCS
    df_final[0].write.csv("gs://my-zhe-414813/conrad_output", mode="overwrite", header=True, inferSchema=True)
    ^^^^^^^^^^^^^^^^^
AttributeError: 'str' object has no attribute 'write'
[2024-04-04T13:42:47.559+0000] {taskinstance.py:1149} INFO - Marking task as UP_FOR_RETRY. dag_id=conrad_coding_test, task_id=task_3_data_output, execution_date=20240404T134213, start_date=20240404T134247, end_date=20240404T134247
[2024-04-04T13:42:47.571+0000] {standard_task_runner.py:107} ERROR - Failed to execute job 36 for task task_3_data_output ('str' object has no attribute 'write'; 160901)
[2024-04-04T13:42:47.603+0000] {local_task_job_runner.py:234} INFO - Task exited with return code 1
[2024-04-04T13:42:47.624+0000] {taskinstance.py:3312} INFO - 0 downstream tasks scheduled from follow-on schedule check
